Workbook

Sheet Resumo
A1: Prospecção Nordeste — Expo MultiMix 2027
A2: Empresas que expõem em feiras do Nordeste e não expuseram na Expo MultiMix em 2026. Levantamento de 22/09/2026.
A4: Prospects na lista | B4: =COUNTA('Prospects Nordeste'!A2:A107)
A5: Nunca expuseram na Expo MultiMix | B5: =COUNTIF('Prospects Nordeste'!E2:E107,"Nunca*")
A6: Ex-clientes que não voltaram em 2026 | B6: =COUNTIF('Prospects Nordeste'!E2:E107,"Ex*")
A7: Prioridade Alta | B7: =COUNTIF('Prospects Nordeste'!D2:D107,"Alta")
A8: Prioridade Média | B8: =COUNTIF('Prospects Nordeste'!D2:D107,"Média")
A9: Prioridade Baixa | B9: =COUNTIF('Prospects Nordeste'!D2:D107,"Baixa")
A10: Com site ou telefone identificado | B10: =SUMPRODUCT(--((LEN('Prospects Nordeste'!H2:H107)+LEN('Prospects Nordeste'!J2:J107))>0))
A12: Andamento
A13: A contatar | B13: =COUNTIF('Prospects Nordeste'!M2:M107,"A contatar")
A14: Contatado | B14: =COUNTIF('Prospects Nordeste'!M2:M107,"Contatado")
A15: Interessado | B15: =COUNTIF('Prospects Nordeste'!M2:M107,"Interessado")
A16: Proposta enviada | B16: =COUNTIF('Prospects Nordeste'!M2:M107,"Proposta enviada")
A17: Fechado | B17: =COUNTIF('Prospects Nordeste'!M2:M107,"Fechado")
A18: Sem interesse | B18: =COUNTIF('Prospects Nordeste'!M2:M107,"Sem interesse")
A20: Clientes ativos que também vão às feiras do Nordeste | B20: =COUNTA('Clientes nas feiras NE'!A5:A34)
A22: Como usar
A23: • Aba "Prospects Nordeste": preencha as colunas amarelas (Responsável, Status, Data, Próximo passo). O Status tem lista suspensa; o Resumo se atualiza sozinho.
A24: • Prioridade (fórmula): Alta = ex-cliente ou presente em 3+ edições no Nordeste; Média = 2 edições; Baixa = 1 edição.
A25: • Aba "Clientes nas feiras NE": clientes atuais que também expõem na Showutil/Showbrinq — foco em fidelização.
A27: Fontes e limites
A28: • Showutil: logos da seção "Expositores da última edição" de cada edição 2026 (showutil.com.br). Nomes lidos do nome do arquivo de cada logo; ~15 logos sem nome no arquivo não puderam ser identificados.
A29: • Showbrinq: não publica lista de expositores; empresas incluídas só com post/notícia que comprove a participação.
A30: • Base Expo MultiMix: receitas por cliente nas edições Manaus/Belém 2025 e 2026 (sistema de gestão).
A31: • Segmento, sede, site e telefone: pesquisa web automática; campos em branco = não identificado com segurança. Conferir antes do contato.

Sheet Prospects Nordeste
A1: Empresa | B1: Feiras no Nordeste (2026) | C1: Nº de edições | D1: Prioridade | E1: Situação na Expo MultiMix | F1: Segmento | G1: Sede | H1: Site | I1: Instagram | J1: Telefone / WhatsApp | K1: Fonte da participação | L1: Responsável | M1: Status do contato | N1: Data do contato | O1: Próximo passo / observações
A2: Matrix | B2: Caruaru/PE mar-2026; Caruaru/PE out-2026 | C2: 2 | D2: =IF(LEFT(E2,2)="Ex","Alta",IF(C2>=3,"Alta",IF(C2=2,"Média","Baixa"))) | E2: Ex-cliente (última: 2025 Belém) — não voltou em 2026 | K2: showutil.com.br (logos "Expositores da última edição") | M2: A contatar
A3: Mel Toys / Beija-Flor | B3: Caruaru/PE mar-2026; Caruaru/PE out-2026 | C3: 2 | D3: =IF(LEFT(E3,2)="Ex","Alta",IF(C3>=3,"Alta",IF(C3=2,"Média","Baixa"))) | E3: Ex-cliente (última: 2025 Belém) — não voltou em 2026 | K3: showutil.com.br (logos "Expositores da última edição") | M3: A contatar
A4: Barufe Incensos | B4: Caruaru/PE mar-2026 | C4: 1 | D4: =IF(LEFT(E4,2)="Ex","Alta",IF(C4>=3,"Alta",IF(C4=2,"Média","Baixa"))) | E4: Ex-cliente (última: 2025 Belém) — não voltou em 2026 | K4: showutil.com.br (logos "Expositores da última edição") | M4: A contatar
A5: Alumínio Vieira | B5: Caruaru/PE mar-2026; Caruaru/PE out-2026; Feira de Santana/BA mar-2026; Feira de Santana/BA out-2026; São Luís/MA mar-2026 | C5: 5 | D5: =IF(LEFT(E5,2)="Ex","Alta",IF(C5>=3,"Alta",IF(C5=2,"Média","Baixa"))) | E5: Nunca expôs | K5: showutil.com.br (logos "Expositores da última edição") | M5: A contatar
A6: Belareal | B6: Caruaru/PE mar-2026; Caruaru/PE out-2026; Feira de Santana/BA mar-2026; Feira de Santana/BA out-2026; São Luís/MA mar-2026 | C6: 5 | D6: =IF(LEFT(E6,2)="Ex","Alta",IF(C6>=3,"Alta",IF(C6=2,"Média","Baixa"))) | E6: Nunca expôs | K6: showutil.com.br (logos "Expositores da última edição") | M6: A contatar
A7: Distribuidores Vieira | B7: Caruaru/PE mar-2026; Caruaru/PE out-2026; Feira de Santana/BA mar-2026; Feira de Santana/BA out-2026; São Luís/MA mar-2026 | C7: 5 | D7: =IF(LEFT(E7,2)="Ex","Alta",IF(C7>=3,"Alta",IF(C7=2,"Média","Baixa"))) | E7: Nunca expôs | K7: showutil.com.br (logos "Expositores da última edição") | M7: A contatar
A8: Disbal | B8: Caruaru/PE mar-2026; Caruaru/PE out-2026; Feira de Santana/BA mar-2026; São Luís/MA mar-2026 | C8: 4 | D8: =IF(LEFT(E8,2)="Ex","Alta",IF(C8>=3,"Alta",IF(C8=2,"Média","Baixa"))) | E8: Nunca expôs | F8: Distribuidor/atacado de UD (vidros, térmicos, plásticos, brinquedos, decoração) | G8: Feira de Santana/BA | H8: https://disbal.com.br | J8: (75) 3322-3838 / (75) 3021-7400 | K8: showutil.com.br (logos "Expositores da última edição") | M8: A contatar
A9: Jxpbrink | B9: Showbrinq Caruaru/PE jul-2026; Showbrinq Feira de Santana/BA jul-2026; Showbrinq Fortaleza/CE jul-2026; Showbrinq São Luís/MA jul-2026 | C9: 4 | D9: =IF(LEFT(E9,2)="Ex","Alta",IF(C9>=3,"Alta",IF(C9=2,"Média","Baixa"))) | E9: Nunca expôs | F9: Brinquedos | K9: https://www.instagram.com/reel/DaNSMOoBy7N/ | https://www.instagram.com/reel/DacvDDOhYWY/ | https://www.facebook.com/61565565620720/videos/1856783761982079/ | https://www.instagram.com/p/DaAsXtltUcE/ | M9: A contatar
A10: Lummar Brinquedos | B10: Caruaru/PE mar-2026; Caruaru/PE out-2026; Feira de Santana/BA mar-2026; São Luís/MA mar-2026 | C10: 4 | D10: =IF(LEFT(E10,2)="Ex","Alta",IF(C10>=3,"Alta",IF(C10=2,"Média","Baixa"))) | E10: Nunca expôs | K10: showutil.com.br (logos "Expositores da última edição") | M10: A contatar
A11: Lummar Plásticos | B11: Caruaru/PE mar-2026; Caruaru/PE out-2026; Feira de Santana/BA mar-2026; São Luís/MA mar-2026 | C11: 4 | D11: =IF(LEFT(E11,2)="Ex","Alta",IF(C11>=3,"Alta",IF(C11=2,"Média","Baixa"))) | E11: Nunca expôs | K11: showutil.com.br (logos "Expositores da última edição") | M11: A contatar
A12: Mtoys | B12: Caruaru/PE mar-2026; Caruaru/PE out-2026; Feira de Santana/BA out-2026; São Luís/MA mar-2026 | C12: 4 | D12: =IF(LEFT(E12,2)="Ex","Alta",IF(C12>=3,"Alta",IF(C12=2,"Média","Baixa"))) | E12: Nunca expôs | K12: showutil.com.br (logos "Expositores da última edição") | M12: A contatar
A13: Praticasa | B13: Caruaru/PE mar-2026; Caruaru/PE out-2026; Feira de Santana/BA mar-2026; São Luís/MA mar-2026 | C13: 4 | D13: =IF(LEFT(E13,2)="Ex","Alta",IF(C13>=3,"Alta",IF(C13=2,"Média","Baixa"))) | E13: Nunca expôs | K13: showutil.com.br (logos "Expositores da última edição") | M13: A contatar
A14: Real | B14: Caruaru/PE mar-2026; Caruaru/PE out-2026; Feira de Santana/BA out-2026; São Luís/MA mar-2026 | C14: 4 | D14: =IF(LEFT(E14,2)="Ex","Alta",IF(C14>=3,"Alta",IF(C14=2,"Média","Baixa"))) | E14: Nunca expôs | K14: showutil.com.br (logos "Expositores da última edição") | M14: A contatar
A15: Atacaplast | B15: Caruaru/PE mar-2026; Caruaru/PE out-2026; Feira de Santana/BA mar-2026 | C15: 3 | D15: =IF(LEFT(E15,2)="Ex","Alta",IF(C15>=3,"Alta",IF(C15=2,"Média","Baixa"))) | E15: Nunca expôs | K15: showutil.com.br (logos "Expositores da última edição") | M15: A contatar
A16: Clink | B16: Caruaru/PE mar-2026; Caruaru/PE out-2026; Feira de Santana/BA mar-2026 | C16: 3 | D16: =IF(LEFT(E16,2)="Ex","Alta",IF(C16>=3,"Alta",IF(C16=2,"Média","Baixa"))) | E16: Nunca expôs | F16: Importador/atacado de UD (organização, cozinha, banheiro) | H16: https://clinkimport.com | K16: showutil.com.br (logos "Expositores da última edição") | M16: A contatar
A17: Dimix | B17: Caruaru/PE mar-2026; Caruaru/PE out-2026; Feira de Santana/BA mar-2026 | C17: 3 | D17: =IF(LEFT(E17,2)="Ex","Alta",IF(C17>=3,"Alta",IF(C17=2,"Média","Baixa"))) | E17: Nunca expôs | K17: showutil.com.br (logos "Expositores da última edição") | M17: A contatar
A18: Dmplas | B18: Caruaru/PE mar-2026; Feira de Santana/BA mar-2026; São Luís/MA mar-2026 | C18: 3 | D18: =IF(LEFT(E18,2)="Ex","Alta",IF(C18>=3,"Alta",IF(C18=2,"Média","Baixa"))) | E18: Nunca expôs | K18: showutil.com.br (logos "Expositores da última edição") | M18: A contatar
A19: Fort Tudo | B19: Caruaru/PE mar-2026; Caruaru/PE out-2026; São Luís/MA mar-2026 | C19: 3 | D19: =IF(LEFT(E19,2)="Ex","Alta",IF(C19>=3,"Alta",IF(C19=2,"Média","Baixa"))) | E19: Nunca expôs | K19: showutil.com.br (logos "Expositores da última edição") | M19: A contatar
A20: Geonave | B20: Caruaru/PE mar-2026; Feira de Santana/BA mar-2026; São Luís/MA mar-2026 | C20: 3 | D20: =IF(LEFT(E20,2)="Ex","Alta",IF(C20>=3,"Alta",IF(C20=2,"Média","Baixa"))) | E20: Nunca expôs | K20: showutil.com.br (logos "Expositores da última edição") | M20: A contatar
A21: Horaplast | B21: Caruaru/PE mar-2026; Caruaru/PE out-2026; Feira de Santana/BA out-2026 | C21: 3 | D21: =IF(LEFT(E21,2)="Ex","Alta",IF(C21>=3,"Alta",IF(C21=2,"Média","Baixa"))) | E21: Nunca expôs | K21: showutil.com.br (logos "Expositores da última edição") | M21: A contatar
A22: Inga Import | B22: Caruaru/PE mar-2026; Caruaru/PE out-2026; São Luís/MA mar-2026 | C22: 3 | D22: =IF(LEFT(E22,2)="Ex","Alta",IF(C22>=3,"Alta",IF(C22=2,"Média","Baixa"))) | E22: Nunca expôs | K22: showutil.com.br (logos "Expositores da última edição") | M22: A contatar
A23: Jambo | B23: Caruaru/PE mar-2026; Feira de Santana/BA mar-2026; São Luís/MA mar-2026 | C23: 3 | D23: =IF(LEFT(E23,2)="Ex","Alta",IF(C23>=3,"Alta",IF(C23=2,"Média","Baixa"))) | E23: Nunca expôs | K23: showutil.com.br (logos "Expositores da última edição") | M23: A contatar
A24: Mev Glass | B24: Caruaru/PE mar-2026; Caruaru/PE out-2026; São Luís/MA mar-2026 | C24: 3 | D24: =IF(LEFT(E24,2)="Ex","Alta",IF(C24>=3,"Alta",IF(C24=2,"Média","Baixa"))) | E24: Nunca expôs | K24: showutil.com.br (logos "Expositores da última edição") | M24: A contatar
A25: Mimo Style | B25: Caruaru/PE mar-2026; Feira de Santana/BA mar-2026; São Luís/MA mar-2026 | C25: 3 | D25: =IF(LEFT(E25,2)="Ex","Alta",IF(C25>=3,"Alta",IF(C25=2,"Média","Baixa"))) | E25: Nunca expôs | K25: showutil.com.br (logos "Expositores da última edição") | M25: A contatar
A26: Nautika | B26: Caruaru/PE mar-2026; Feira de Santana/BA mar-2026; São Luís/MA mar-2026 | C26: 3 | D26: =IF(LEFT(E26,2)="Ex","Alta",IF(C26>=3,"Alta",IF(C26=2,"Média","Baixa"))) | E26: Nunca expôs | K26: showutil.com.br (logos "Expositores da última edição") | M26: A contatar
A27: Omniteca | B27: Showbrinq Fortaleza/CE jul-2026; Caruaru/PE out-2026; Feira de Santana/BA out-2026 | C27: 3 | D27: =IF(LEFT(E27,2)="Ex","Alta",IF(C27>=3,"Alta",IF(C27=2,"Média","Baixa"))) | E27: Nunca expôs | K27: showutil.com.br (logos "Expositores da última edição") | https://www.instagram.com/reel/Dai8G_cN9cJ/ | M27: A contatar
A28: Plasbrink / Ligbrin | B28: Caruaru/PE mar-2026; Caruaru/PE out-2026; Feira de Santana/BA out-2026 | C28: 3 | D28: =IF(LEFT(E28,2)="Ex","Alta",IF(C28>=3,"Alta",IF(C28=2,"Média","Baixa"))) | E28: Nunca expôs | K28: showutil.com.br (logos "Expositores da última edição") | M28: A contatar
... A31: Ápice | B31: Caruaru/PE mar-2026; Caruaru/PE out-2026; Feira de Santana/BA mar-2026 | C31: 3 | D31: =IF(LEFT(E31,2)="Ex","Alta",IF(C31>=3,"Alta",IF(C31=2,"Média","Baixa"))) | E31: Nunca expôs | K31: showutil.com.br (logos "Expositores da última edição") | M31: A contatar
A32: Amazônia Aromas | B32: Caruaru/PE mar-2026; Caruaru/PE out-2026 | C32: 2 | D32: =IF(LEFT(E32,2)="Ex","Alta",IF(C32>=3,"Alta",IF(C32=2,"Média","Baixa"))) | E32: Nunca expôs | F32: Aromas, difusores, perfumes de ambiente | G32: Guarulhos/SP | H32: https://amazoniaaromas.com.br | I32: instagram.com/amazoniaaromas | J32: (11) 2496-1659 / WhatsApp (11) 96180-2804 | K32: showutil.com.br (logos "Expositores da última edição") | M32: A contatar
A33: Aço Forte | B33: Caruaru/PE mar-2026; São Luís/MA mar-2026 | C33: 2 | D33: =IF(LEFT(E33,2)="Ex","Alta",IF(C33>=3,"Alta",IF(C33=2,"Média","Baixa"))) | E33: Nunca expôs | K33: showutil.com.br (logos "Expositores da última edição") | M33: A contatar
A34: Bellagio | B34: Caruaru/PE mar-2026; Caruaru/PE out-2026 | C34: 2 | D34: =IF(LEFT(E34,2)="Ex","Alta",IF(C34>=3,"Alta",IF(C34=2,"Média","Baixa"))) | E34: Nunca expôs | K34: showutil.com.br (logos "Expositores da última edição") | M34: A contatar
A35: Casa Bela | B35: Caruaru/PE mar-2026; Caruaru/PE out-2026 | C35: 2 | D35: =IF(LEFT(E35,2)="Ex","Alta",IF(C35>=3,"Alta",IF(C35=2,"Média","Baixa"))) | E35: Nunca expôs | K35: showutil.com.br (logos "Expositores da última edição") | M35: A contatar
A36: Fenima | B36: Caruaru/PE out-2026; Feira de Santana/BA out-2026 | C36: 2 | D36: =IF(LEFT(E36,2)="Ex","Alta",IF(C36>=3,"Alta",IF(C36=2,"Média","Baixa"))) | E36: Nunca expôs | K36: showutil.com.br (logos "Expositores da última edição") | M36: A contatar
A37: Injetemp | B37: Caruaru/PE mar-2026; São Luís/MA mar-2026 | C37: 2 | D37: =IF(LEFT(E37,2)="Ex","Alta",IF(C37>=3,"Alta",IF(C37=2,"Média","Baixa"))) | E37: Nunca expôs | K37: showutil.com.br (logos "Expositores da última edição") | M37: A contatar
A38: Inkplas | B38: Caruaru/PE mar-2026; São Luís/MA mar-2026 | C38: 2 | D38: =IF(LEFT(E38,2)="Ex","Alta",IF(C38>=3,"Alta",IF(C38=2,"Média","Baixa"))) | E38: Nunca expôs | F38: UD plásticas (indústria) | G38: Eusébio/CE | K38: showutil.com.br (logos "Expositores da última edição") | M38: A contatar
A39: Inplast | B39: Caruaru/PE out-2026; São Luís/MA mar-2026 | C39: 2 | D39: =IF(LEFT(E39,2)="Ex","Alta",IF(C39>=3,"Alta",IF(C39=2,"Média","Baixa"))) | E39: Nunca expôs | F39: UD plásticas (indústria) | G39: Pedreira/SP | H39: https://www.inplast.ind.br | J39: (19) 3852-9700 / WhatsApp (19) 98424-0666 | K39: showutil.com.br (logos "Expositores da última edição") | M39: A contatar
A40: Jr Aluminio | B40: Caruaru/PE mar-2026; Caruaru/PE out-2026 | C40: 2 | D40: =IF(LEFT(E40,2)="Ex","Alta",IF(C40>=3,"Alta",IF(C40=2,"Média","Baixa"))) | E40: Nunca expôs | F40: UD em alumínio fundido (panelas) | G40: MG | H40: http://aluminiojr.com.br | K40: showutil.com.br (logos "Expositores da última edição") | M40: A contatar
A41: Julifix | B41: Caruaru/PE mar-2026; São Luís/MA mar-2026 | C41: 2 | D41: =IF(LEFT(E41,2)="Ex","Alta",IF(C41>=3,"Alta",IF(C41=2,"Média","Baixa"))) | E41: Nunca expôs | K41: showutil.com.br (logos "Expositores da última edição") | M41: A contatar
A42: Marilu | B42: Caruaru/PE mar-2026; Caruaru/PE out-2026 | C42: 2 | D42: =IF(LEFT(E42,2)="Ex","Alta",IF(C42>=3,"Alta",IF(C42=2,"Média","Baixa"))) | E42: Nunca expôs | K42: showutil.com.br (logos "Expositores da última edição") | M42: A contatar
...

Sheet Clientes nas feiras NE
A1: Clientes ativos da Expo MultiMix que também expõem em feiras do Nordeste (Showutil / Showbrinq)
A2: Essas feiras disputam o mesmo grupo de fornecedores. Use para fidelizar: são os primeiros a receber condições para 2027.
A4: Cliente | B4: Edições Expo MultiMix (2025–2026) | C4: Nº edições no Nordeste 2026 | D4: Feiras no Nordeste 2026
A5: Plasberg | B5: 2026 Belém | C5: 5 | D5: Caruaru/PE mar-2026; Caruaru/PE out-2026; Feira de Santana/BA mar-2026; Feira de Santana/BA out-2026; São Luís/MA mar-2026
A6: Arca Plast | B6: 2025 Belém, 2026 Belém | C6: 5 | D6: Caruaru/PE mar-2026; Caruaru/PE out-2026; Feira de Santana/BA mar-2026; Feira de Santana/BA out-2026; São Luís/MA mar-2026
A7: Plasti.Co | B7: 2026 Manaus, 2026 Belém | C7: 4 | D7: Caruaru/PE mar-2026; Caruaru/PE out-2026; Feira de Santana/BA mar-2026; São Luís/MA mar-2026
A8: Intimate | B8: 2026 Manaus, 2026 Belém | C8: 4 | D8: Caruaru/PE mar-2026; Caruaru/PE out-2026; Feira de Santana/BA mar-2026; São Luís/MA mar-2026
A9: Luz Aluminio / Luz Panelas | B9: 2025 Manaus, 2025 Belém, 2026 Manaus, 2026 Belém | C9: 4 | D9: Caruaru/PE mar-2026; Caruaru/PE out-2026; Feira de Santana/BA mar-2026; São Luís/MA mar-2026
A10: Unitermi | B10: 2025 Manaus, 2025 Belém, 2026 Manaus, 2026 Belém | C10: 3 | D10: Caruaru/PE mar-2026; Caruaru/PE out-2026; São Luís/MA mar-2026
A11: Plasmont | B11: 2026 Belém | C11: 3 | D11: Caruaru/PE mar-2026; Caruaru/PE out-2026; São Luís/MA mar-2026
A12: For-Plast | B12: 2025 Belém, 2026 Belém | C12: 3 | D12: Caruaru/PE mar-2026; Caruaru/PE out-2026; São Luís/MA mar-2026
A13: Merconplas | B13: 2025 Manaus, 2026 Manaus | C13: 3 | D13: Caruaru/PE mar-2026; Feira de Santana/BA mar-2026; São Luís/MA mar-2026
A14: Xpert | B14: 2026 Belém | C14: 3 | D14: Caruaru/PE mar-2026; Caruaru/PE out-2026; São Luís/MA mar-2026
A15: Lp House (Samba) | B15: 2026 Belém | C15: 3 | D15: Caruaru/PE mar-2026; Feira de Santana/BA mar-2026; São Luís/MA mar-2026
A16: Tilin | B16: 2025 Belém, 2026 Belém | C16: 3 | D16: Showbrinq 2026; Caruaru/PE mar-2026; Caruaru/PE out-2026
... A34: Brinquedos Anjo | B34: 2025 Belém, 2026 Belém | C34: 1 | D34: Showbrinq 2026

Sheet Calendário Nordeste
A1: Feiras B2B no Nordeste nos nossos segmentos
A3: Feira | B3: Cidade/UF | C3: Local | D3: Data | E3: Segmento | F3: Lista de expositores pública? | G3: Fonte
A4: Showutil (1º sem.) | B4: Caruaru/PE | C4: Caruaru Shopping | D4: 10–12/mar/2026 | E4: Utilidades, presentes, brinquedos, bazar | F4: Sim (logos no site) | G4: https://showutil.com.br/pernambuco/
A5: Showutil (1º sem.) | B5: São Luís/MA | C5: Sebrae Multicenter | D5: 17–19/mar/2026 | E5: Utilidades, presentes, brinquedos, bazar | F5: Sim (logos no site) | G5: https://showutil.com.br/maranhao/
A6: Showutil (1º sem.) | B6: Feira de Santana/BA | C6: Olimpo Eventos | D6: 25–27/mar/2026 | E6: Utilidades, presentes, brinquedos, bazar | F6: Sim (logos no site) | G6: https://showutil.com.br/bahia/
A7: Showbrinq | B7: São Luís/MA | C7: Multicenter | D7: 1–3/jul/2026 | E7: Brinquedos | F7: Não | G7: https://www.showbrinq.com.br/maranhao/
A8: Showbrinq | B8: Fortaleza/CE | C8: Centro de Eventos do Ceará | D8: 7–9/jul/2026 | E8: Brinquedos | F8: Não | G8: https://centrodeeventos.ce.gov.br/evento/showbrinq-2026/
A9: Showbrinq | B9: Caruaru/PE | C9: Expocenter Caruaru | D9: 14–16/jul/2026 | E9: Brinquedos | F9: Não | G9: https://www.facebook.com/xalingo/posts/1451356533699331/
A10: Showbrinq | B10: Feira de Santana/BA | C10: — | D10: 21–23/jul/2026 | E10: Brinquedos | F10: Não | G10: https://www.instagram.com/p/Da5QC15Enwc/
A11: SuperBahia | B11: Salvador/BA | C11: Centro de Convenções | D11: 28–30/jul/2026 | E11: Varejo alimentar / supermercados | F11: Não | G11: https://g1.globo.com/ba/bahia/noticia/2026/07/28/superbahia-em-salvador.ghtml
A12: Showutil (2º sem.) | B12: Caruaru/PE | C12: WA Convention – Caruaru Shopping | D12: 20–22/out/2026 | E12: Utilidades, presentes, brinquedos, bazar | F12: Sim (logos no site) | G12: https://showutil.com.br/pernambuco2/
A13: Showutil (2º sem.) | B13: Feira de Santana/BA | C13: Spazio Eventos | D13: 27–29/out/2026 | E13: Utilidades, presentes, brinquedos, bazar | F13: Sim (logos no site) | G13: https://showutil.com.br/bahia2
A14: Showbrinq | B14: São Luís/MA | C14: Multicenter | D14: 29/jun–1/jul/2027 | E14: Brinquedos | F14: Não | G14: https://www.showbrinq.com.br/
... A20: Expo MultiMix Belém (referência) | B20: Belém/PA | C20: Estação das Docas | D20: 15–17/jun/2027 | E20: Multissetorial | F20: — | G20: https://www.expomultimix.com.br/belem
